Traceback (most recent call last):
  File "/Users/shreya/Desktop/MASCoT/senti/lib/python3.12/site-packages/huggingface_hub/utils/_http.py", line 409, in hf_raise_for_status
    response.raise_for_status()
  File "/Users/shreya/Desktop/MASCoT/senti/lib/python3.12/site-packages/requests/models.py", line 1024, in raise_for_status
    raise HTTPError(http_error_msg, response=self)
requests.exceptions.HTTPError: 401 Client Error: Unauthorized for url: https://huggingface.co/meta-llama/Llama-2-7b/resolve/main/config.json

The above exception was the direct cause of the following exception:

Traceback (most recent call last):
  File "/Users/shreya/Desktop/MASCoT/senti/lib/python3.12/site-packages/transformers/utils/hub.py", line 342, in cached_file
    resolved_file = hf_hub_download(
                    ^^^^^^^^^^^^^^^^
  File "/Users/shreya/Desktop/MASCoT/senti/lib/python3.12/site-packages/huggingface_hub/utils/_validators.py", line 114, in _inner_fn
    return fn(*args, **kwargs)
           ^^^^^^^^^^^^^^^^^^^
  File "/Users/shreya/Desktop/MASCoT/senti/lib/python3.12/site-packages/huggingface_hub/file_download.py", line 862, in hf_hub_download
    return _hf_hub_download_to_cache_dir(
           ^^^^^^^^^^^^^^^^^^^^^^^^^^^^^^
  File "/Users/shreya/Desktop/MASCoT/senti/lib/python3.12/site-packages/huggingface_hub/file_download.py", line 969, in _hf_hub_download_to_cache_dir
    _raise_on_head_call_error(head_call_error, force_download, local_files_only)
  File "/Users/shreya/Desktop/MASCoT/senti/lib/python3.12/site-packages/huggingface_hub/file_download.py", line 1486, in _raise_on_head_call_error
    raise head_call_error
  File "/Users/shreya/Desktop/MASCoT/senti/lib/python3.12/site-packages/huggingface_hub/file_download.py", line 1376, in _get_metadata_or_catch_error
    metadata = get_hf_file_metadata(
               ^^^^^^^^^^^^^^^^^^^^^
  File "/Users/shreya/Desktop/MASCoT/senti/lib/python3.12/site-packages/huggingface_hub/utils/_validators.py", line 114, in _inner_fn
    return fn(*args, **kwargs)
           ^^^^^^^^^^^^^^^^^^^
  File "/Users/shreya/Desktop/MASCoT/senti/lib/python3.12/site-packages/huggingface_hub/file_download.py", line 1296, in get_hf_file_metadata
    r = _request_wrapper(
        ^^^^^^^^^^^^^^^^^
  File "/Users/shreya/Desktop/MASCoT/senti/lib/python3.12/site-packages/huggingface_hub/file_download.py", line 280, in _request_wrapper
    response = _request_wrapper(
               ^^^^^^^^^^^^^^^^^
  File "/Users/shreya/Desktop/MASCoT/senti/lib/python3.12/site-packages/huggingface_hub/file_download.py", line 304, in _request_wrapper
    hf_raise_for_status(response)
  File "/Users/shreya/Desktop/MASCoT/senti/lib/python3.12/site-packages/huggingface_hub/utils/_http.py", line 426, in hf_raise_for_status
    raise _format(GatedRepoError, message, response) from e
huggingface_hub.errors.GatedRepoError: 401 Client Error. (Request ID: Root=1-67b7f6c2-02879f94490f9112577b314d;a0feb68d-7ca6-42de-9558-d235027c0a9a)

Cannot access gated repo for url https://huggingface.co/meta-llama/Llama-2-7b/resolve/main/config.json.
Access to model meta-llama/Llama-2-7b is restricted. You must have access to it and be authenticated to access it. Please log in.

The above exception was the direct cause of the following exception:

Traceback (most recent call last):
  File "/Users/shreya/Desktop/MASCoT/train.py", line 123, in <module>
    main()
  File "/Users/shreya/Desktop/MASCoT/train.py", line 21, in main
    tokenizer = AutoTokenizer.from_pretrained(config.model_name)
                ^^^^^^^^^^^^^^^^^^^^^^^^^^^^^^^^^^^^^^^^^^^^^^^^
  File "/Users/shreya/Desktop/MASCoT/senti/lib/python3.12/site-packages/transformers/models/auto/tokenization_auto.py", line 901, in from_pretrained
    config = AutoConfig.from_pretrained(
             ^^^^^^^^^^^^^^^^^^^^^^^^^^^
  File "/Users/shreya/Desktop/MASCoT/senti/lib/python3.12/site-packages/transformers/models/auto/configuration_auto.py", line 1075, in from_pretrained
    config_dict, unused_kwargs = PretrainedConfig.get_config_dict(pretrained_model_name_or_path, **kwargs)
                                 ^^^^^^^^^^^^^^^^^^^^^^^^^^^^^^^^^^^^^^^^^^^^^^^^^^^^^^^^^^^^^^^^^^^^^^^^^
  File "/Users/shreya/Desktop/MASCoT/senti/lib/python3.12/site-packages/transformers/configuration_utils.py", line 594, in get_config_dict
    config_dict, kwargs = cls._get_config_dict(pretrained_model_name_or_path, **kwargs)
                          ^^^^^^^^^^^^^^^^^^^^^^^^^^^^^^^^^^^^^^^^^^^^^^^^^^^^^^^^^^^^^
  File "/Users/shreya/Desktop/MASCoT/senti/lib/python3.12/site-packages/transformers/configuration_utils.py", line 653, in _get_config_dict
    resolved_config_file = cached_file(
                           ^^^^^^^^^^^^
  File "/Users/shreya/Desktop/MASCoT/senti/lib/python3.12/site-packages/transformers/utils/hub.py", line 360, in cached_file
    raise EnvironmentError(
OSError: You are trying to access a gated repo.
Make sure to have access to it at https://huggingface.co/meta-llama/Llama-2-7b.
401 Client Error. (Request ID: Root=1-67b7f6c2-02879f94490f9112577b314d;a0feb68d-7ca6-42de-9558-d235027c0a9a)

Cannot access gated repo for url https://huggingface.co/meta-llama/Llama-2-7b/resolve/main/config.json.
Access to model meta-llama/Llama-2-7b is restricted. You must have access to it and be authenticated to access it. Please log in.
